Workbook

Sheet 看板
A2: 家电上门服务｜履约监控看板
A3: 600 条合成工单 · 2026-09-30 截止 · 北京时间
A6: 工单量 | D6: 准时上门率 | G6: 按期完工率 | J6: 投诉率 | M6: 异常闭环率
A7: =分组汇总!B9 -> 600 | D7: =分组汇总!D9 -> 0.78166667 | G7: =分组汇总!F9 -> 0.84333333 | J7: =分组汇总!H9 -> 0.066666667 | M7: =分组汇总!K9 -> 0.53932584
A10: 城市 | B10: 准时上门率 | C10: 按期完工率 | D10: 工单量
A11: =分组汇总!A6 -> 北京 | B11: =分组汇总!D6 -> 0.81746032 | C11: =分组汇总!F6 -> 0.88492063 | D11: =分组汇总!B6 -> 252
A12: =分组汇总!A7 -> 武汉 | B12: =分组汇总!D7 -> 0.77202073 | C12: =分组汇总!F7 -> 0.83937824 | D12: =分组汇总!B7 -> 193
A13: =分组汇总!A8 -> 重庆 | B13: =分组汇总!D8 -> 0.73548387 | C13: =分组汇总!F8 -> 0.78064516 | D13: =分组汇总!B8 -> 155
A18: 站点 | B18: 异常闭环率 | C18: 异常单数 | D18: 工单量
A19: =分组汇总!A22 -> BJ01 | B19: =分组汇总!K22 -> 0.34782609 | C19: =分组汇总!I22 -> 23 | D19: =分组汇总!B22 -> 128
A20: =分组汇总!A23 -> BJ02 | B20: =分组汇总!K23 -> 0.63157895 | C20: =分组汇总!I23 -> 38 | D20: =分组汇总!B23 -> 124
A21: =分组汇总!A24 -> WH01 | B21: =分组汇总!K24 -> 0.35 | C21: =分组汇总!I24 -> 20 | D21: =分组汇总!B24 -> 94
A22: =分组汇总!A25 -> WH02 | B22: =分组汇总!K25 -> 0.58974359 | C22: =分组汇总!I25 -> 39 | D22: =分组汇总!B25 -> 99
A23: =分组汇总!A26 -> CQ01 | B23: =分组汇总!K26 -> 0.53125 | C23: =分组汇总!I26 -> 32 | D23: =分组汇总!B26 -> 79
A24: =分组汇总!A27 -> CQ02 | B24: =分组汇总!K27 -> 0.65384615 | C24: =分组汇总!I27 -> 26 | D24: =分组汇总!B27 -> 76
A27: 待关注：WH02 上门异常 17/99；CQ01 完工异常 13/79。
A28: 站点差异是生成器预设的练习情景，不能推断真实根因或改善成效。
A30: 口径：准时上门／按期完工／投诉以 600 单为分母；闭环以 178 条异常为分母。

Sheet 分组汇总
A2: 分组汇总｜履约与异常闭环
A3: 2026-09-30 截止 · 北京时间 · 合成样本
A5: 分组 | B5: 工单量 | C5: 准时上门数 | D5: 准时上门率 | E5: 按期完工数 | F5: 按期完工率 | G5: 投诉数 | H5: 投诉率 | I5: 异常单数 | J5: 已闭环数 | K5: 异常闭环率
A6: 北京 | B6: =COUNTIF(工单明细!$B$2:$B$601,$A6) -> 252 | C6: =SUMIF(工单明细!$B$2:$B$601,$A6,工单明细!$Q$2:$Q$601) -> 206 | D6: =IFERROR(C6/B6,0) -> 0.81746032 | E6: =SUMIF(工单明细!$B$2:$B$601,$A6,工单明细!$R$2:$R$601) -> 223 | F6: =IFERROR(E6/B6,0) -> 0.88492063 | G6: =SUMIF(工单明细!$B$2:$B$601,$A6,工单明细!$O$2:$O$601) -> 14 | H6: =IFERROR(G6/B6,0) -> 0.055555556 | I6: =SUMIF(工单明细!$B$2:$B$601,$A6,工单明细!$S$2:$S$601) -> 61 | J6: =SUMIF(工单明细!$B$2:$B$601,$A6,工单明细!$T$2:$T$601) -> 32 | K6: =IFERROR(J6/I6,0) -> 0.52459016
A7: 武汉 | B7: =COUNTIF(工单明细!$B$2:$B$601,$A7) -> 193 | C7: =SUMIF(工单明细!$B$2:$B$601,$A7,工单明细!$Q$2:$Q$601) -> 149 | D7: =IFERROR(C7/B7,0) -> 0.77202073 | E7: =SUMIF(工单明细!$B$2:$B$601,$A7,工单明细!$R$2:$R$601) -> 162 | F7: =IFERROR(E7/B7,0) -> 0.83937824 | G7: =SUMIF(工单明细!$B$2:$B$601,$A7,工单明细!$O$2:$O$601) -> 10 | H7: =IFERROR(G7/B7,0) -> 0.051813472 | I7: =SUMIF(工单明细!$B$2:$B$601,$A7,工单明细!$S$2:$S$601) -> 59 | J7: =SUMIF(工单明细!$B$2:$B$601,$A7,工单明细!$T$2:$T$601) -> 30 | K7: =IFERROR(J7/I7,0) -> 0.50847458
A8: 重庆 | B8: =COUNTIF(工单明细!$B$2:$B$601,$A8) -> 155 | C8: =SUMIF(工单明细!$B$2:$B$601,$A8,工单明细!$Q$2:$Q$601) -> 114 | D8: =IFERROR(C8/B8,0) -> 0.73548387 | E8: =SUMIF(工单明细!$B$2:$B$601,$A8,工单明细!$R$2:$R$601) -> 121 | F8: =IFERROR(E8/B8,0) -> 0.78064516 | G8: =SUMIF(工单明细!$B$2:$B$601,$A8,工单明细!$O$2:$O$601) -> 16 | H8: =IFERROR(G8/B8,0) -> 0.10322581 | I8: =SUMIF(工单明细!$B$2:$B$601,$A8,工单明细!$S$2:$S$601) -> 58 | J8: =SUMIF(工单明细!$B$2:$B$601,$A8,工单明细!$T$2:$T$601) -> 34 | K8: =IFERROR(J8/I8,0) -> 0.5862069
A9: 合计 | B9: =SUM(B6:B8) -> 600 | C9: =SUM(C6:C8) -> 469 | D9: =IFERROR(C9/B9,0) -> 0.78166667 | E9: =SUM(E6:E8) -> 506 | F9: =IFERROR(E9/B9,0) -> 0.84333333 | G9: =SUM(G6:G8) -> 40 | H9: =IFERROR(G9/B9,0) -> 0.066666667 | I9: =SUM(I6:I8) -> 178 | J9: =SUM(J6:J8) -> 96 | K9: =IFERROR(J9/I9,0) -> 0.53932584
A13: 分组 | B13: 工单量 | C13: 准时上门数 | D13: 准时上门率 | E13: 按期完工数 | F13: 按期完工率 | G13: 投诉数 | H13: 投诉率 | I13: 异常单数 | J13: 已闭环数 | K13: 异常闭环率
A14: 安装 | B14: =COUNTIF(工单明细!$C$2:$C$601,$A14) -> 268 | C14: =SUMIF(工单明细!$C$2:$C$601,$A14,工单明细!$Q$2:$Q$601) -> 208 | D14: =IFERROR(C14/B14,0) -> 0.7761194 | E14: =SUMIF(工单明细!$C$2:$C$601,$A14,工单明细!$R$2:$R$601) -> 223 | F14: =IFERROR(E14/B14,0) -> 0.83208955 | G14: =SUMIF(工单明细!$C$2:$C$601,$A14,工单明细!$O$2:$O$601) -> 20 | H14: =IFERROR(G14/B14,0) -> 0.074626866 | I14: =SUMIF(工单明细!$C$2:$C$601,$A14,工单明细!$S$2:$S$601) -> 81 | J14: =SUMIF(工单明细!$C$2:$C$601,$A14,工单明细!$T$2:$T$601) -> 40 | K14: =IFERROR(J14/I14,0) -> 0.49382716
A15: 维修 | B15: =COUNTIF(工单明细!$C$2:$C$601,$A15) -> 245 | C15: =SUMIF(工单明细!$C$2:$C$601,$A15,工单明细!$Q$2:$Q$601) -> 192 | D15: =IFERROR(C15/B15,0) -> 0.78367347 | E15: =SUMIF(工单明细!$C$2:$C$601,$A15,工单明细!$R$2:$R$601) -> 209 | F15: =IFERROR(E15/B15,0) -> 0.85306122 | G15: =SUMIF(工单明细!$C$2:$C$601,$A15,工单明细!$O$2:$O$601) -> 16 | H15: =IFERROR(G15/B15,0) -> 0.065306122 | I15: =SUMIF(工单明细!$C$2:$C$601,$A15,工单明细!$S$2:$S$601) -> 76 | J15: =SUMIF(工单明细!$C$2:$C$601,$A15,工单明细!$T$2:$T$601) -> 46 | K15: =IFERROR(J15/I15,0) -> 0.60526316
A16: 拆旧 | B16: =COUNTIF(工单明细!$C$2:$C$601,$A16) -> 87 | C16: =SUMIF(工单明细!$C$2:$C$601,$A16,工单明细!$Q$2:$Q$601) -> 69 | D16: =IFERROR(C16/B16,0) -> 0.79310345 | E16: =SUMIF(工单明细!$C$2:$C$601,$A16,工单明细!$R$2:$R$601) -> 74 | F16: =IFERROR(E16/B16,0) -> 0.85057471 | G16: =SUMIF(工单明细!$C$2:$C$601,$A16,工单明细!$O$2:$O$601) -> 4 | H16: =IFERROR(G16/B16,0) -> 0.045977011 | I16: =SUMIF(工单明细!$C$2:$C$601,$A16,工单明细!$S$2:$S$601) -> 21 | J16: =SUMIF(工单明细!$C$2:$C$601,$A16,工单明细!$T$2:$T$601) -> 10 | K16: =IFERROR(J16/I16,0) -> 0.47619048
A17: 合计 | B17: =SUM(B14:B16) -> 600 | C17: =SUM(C14:C16) -> 469 | D17: =IFERROR(C17/B17,0) -> 0.78166667 | E17: =SUM(E14:E16) -> 506 | F17: =IFERROR(E17/B17,0) -> 0.84333333 | G17: =SUM(G14:G16) -> 40 | H17: =IFERROR(G17/B17,0) -> 0.066666667 | I17: =SUM(I14:I16) -> 178 | J17: =SUM(J14:J16) -> 96 | K17: =IFERROR(J17/I17,0) -> 0.53932584
A21: 分组 | B21: 工单量 | C21: 准时上门数 | D21: 准时上门率 | E21: 按期完工数 | F21: 按期完工率 | G21: 投诉数 | H21: 投诉率 | I21: 异常单数 | J21: 已闭环数 | K21: 异常闭环率
A22: BJ01 | B22: =COUNTIF(工单明细!$D$2:$D$601,$A22) -> 128 | C22: =SUMIF(工单明细!$D$2:$D$601,$A22,工单明细!$Q$2:$Q$601) -> 108 | D22: =IFERROR(C22/B22,0) -> 0.84375 | E22: =SUMIF(工单明细!$D$2:$D$601,$A22,工单明细!$R$2:$R$601) -> 115 | F22: =IFERROR(E22/B22,0) -> 0.8984375 | G22: =SUMIF(工单明细!$D$2:$D$601,$A22,工单明细!$O$2:$O$601) -> 6 | H22: =IFERROR(G22/B22,0) -> 0.046875 | I22: =SUMIF(工单明细!$D$2:$D$601,$A22,工单明细!$S$2:$S$601) -> 23 | J22: =SUMIF(工单明细!$D$2:$D$601,$A22,工单明细!$T$2:$T$601) -> 8 | K22: =IFERROR(J22/I22,0) -> 0.34782609
A23: BJ02 | B23: =COUNTIF(工单明细!$D$2:$D$601,$A23) -> 124 | C23: =SUMIF(工单明细!$D$2:$D$601,$A23,工单明细!$Q$2:$Q$601) -> 98 | D23: =IFERROR(C23/B23,0) -> 0.79032258 | E23: =SUMIF(工单明细!$D$2:$D$601,$A23,工单明细!$R$2:$R$601) -> 108 | F23: =IFERROR(E23/B23,0) -> 0.87096774 | G23: =SUMIF(工单明细!$D$2:$D$601,$A23,工单明细!$O$2:$O$601) -> 8 | H23: =IFERROR(G23/B23,0) -> 0.064516129 | I23: =SUMIF(工单明细!$D$2:$D$601,$A23,工单明细!$S$2:$S$601) -> 38 | J23: =SUMIF(工单明细!$D$2:$D$601,$A23,工单明细!$T$2:$T$601) -> 24 | K23: =IFERROR(J23/I23,0) -> 0.63157895
A24: WH01 | B24: =COUNTIF(工单明细!$D$2:$D$601,$A24) -> 94 | C24: =SUMIF(工单明细!$D$2:$D$601,$A24,工单明细!$Q$2:$Q$601) -> 78 | D24: =IFERROR(C24/B24,0) -> 0.82978723 | E24: =SUMIF(工单明细!$D$2:$D$601,$A24,工单明细!$R$2:$R$601) -> 81 | F24: =IFERROR(E24/B24,0) -> 0.86170213 | G24: =SUMIF(工单明细!$D$2:$D$601,$A24,工单明细!$O$2:$O$601) -> 4 | H24: =IFERROR(G24/B24,0) -> 0.042553191 | I24: =SUMIF(工单明细!$D$2:$D$601,$A24,工单明细!$S$2:$S$601) -> 20 | J24: =SUMIF(工单明细!$D$2:$D$601,$A24,工单明细!$T$2:$T$601) -> 7 | K24: =IFERROR(J24/I24,0) -> 0.35
A25: WH02 | B25: =COUNTIF(工单明细!$D$2:$D$601,$A25) -> 99 | C25: =SUMIF(工单明细!$D$2:$D$601,$A25,工单明细!$Q$2:$Q$601) -> 71 | D25: =IFERROR(C25/B25,0) -> 0.71717172 | E25: =SUMIF(工单明细!$D$2:$D$601,$A25,工单明细!$R$2:$R$601) -> 81 | F25: =IFERROR(E25/B25,0) -> 0.81818182 | G25: =SUMIF(工单明细!$D$2:$D$601,$A25,工单明细!$O$2:$O$601) -> 6 | H25: =IFERROR(G25/B25,0) -> 0.060606061 | I25: =SUMIF(工单明细!$D$2:$D$601,$A25,工单明细!$S$2:$S$601) -> 39 | J25: =SUMIF(工单明细!$D$2:$D$601,$A25,工单明细!$T$2:$T$601) -> 23 | K25: =IFERROR(J25/I25,0) -> 0.58974359
A26: CQ01 | B26: =COUNTIF(工单明细!$D$2:$D$601,$A26) -> 79 | C26: =SUMIF(工单明细!$D$2:$D$601,$A26,工单明细!$Q$2:$Q$601) -> 60 | D26: =IFERROR(C26/B26,0) -> 0.75949367 | E26: =SUMIF(工单明细!$D$2:$D$601,$A26,工单明细!$R$2:$R$601) -> 56 | F26: =IFERROR(E26/B26,0) -> 0.70886076 | G26: =SUMIF(工单明细!$D$2:$D$601,$A26,工单明细!$O$2:$O$601) -> 9 | H26: =IFERROR(G26/B26,0) -> 0.11392405 | I26: =SUMIF(工单明细!$D$2:$D$601,$A26,工单明细!$S$2:$S$601) -> 32 | J26: =SUMIF(工单明细!$D$2:$D$601,$A26,工单明细!$T$2:$T$601) -> 17 | K26: =IFERROR(J26/I26,0) -> 0.53125
A27: CQ02 | B27: =COUNTIF(工单明细!$D$2:$D$601,$A27) -> 76 | C27: =SUMIF(工单明细!$D$2:$D$601,$A27,工单明细!$Q$2:$Q$601) -> 54 | D27: =IFERROR(C27/B27,0) -> 0.71052632 | E27: =SUMIF(工单明细!$D$2:$D$601,$A27,工单明细!$R$2:$R$601) -> 65 | F27: =IFERROR(E27/B27,0) -> 0.85526316 | G27: =SUMIF(工单明细!$D$2:$D$601,$A27,工单明细!$O$2:$O$601) -> 7 | H27: =IFERROR(G27/B27,0) -> 0.092105263 | I27: =SUMIF(工单明细!$D$2:$D$601,$A27,工单明细!$S$2:$S$601) -> 26 | J27: =SUMIF(工单明细!$D$2:$D$601,$A27,工单明细!$T$2:$T$601) -> 17 | K27: =IFERROR(J27/I27,0) -> 0.65384615
A28: 合计 | B28: =SUM(B22:B27) -> 600 | C28: =SUM(C22:C27) -> 469 | D28: =IFERROR(C28/B28,0) -> 0.78166667 | E28: =SUM(E22:E27) -> 506 | F28: =IFERROR(E28/B28,0) -> 0.84333333 | G28: =SUM(G22:G27) -> 40 | H28: =IFERROR(G28/B28,0) -> 0.066666667 | I28: =SUM(I22:I27) -> 178 | J28: =SUM(J22:J27) -> 96 | K28: =IFERROR(J28/I28,0) -> 0.53932584
A31: 主要异常 | B31: 工单量
A32: 无 | B32: =COUNTIF(工单明细!$V$2:$V$601,A32) -> 422
A33: 派单超时 | B33: =COUNTIF(工单明细!$V$2:$V$601,A33) -> 52
A34: 上门超时 | B34: =COUNTIF(工单明细!$V$2:$V$601,A34) -> 79
A35: 完工超时 | B35: =COUNTIF(工单明细!$V$2:$V$601,A35) -> 47
A36: 合计 | B36: =SUM(B32:B35) -> 600
A38: 源标签一致数 | B38: =SUM(工单明细!W2:W601) -> 600
A39: 分母：准时、按期、投诉均为全部有效工单；闭环率分母仅为异常单。
A40: 原始时间改动后计算异常类型会联动；“源标签一致数”低于 600 时应核查原始标签。

Sheet 透视_城市工单量
A3: 行标签 | B3: 计数项:order_id
A4: 北京 | B4: 252
A5: 武汉 | B5: 193
A6: 重庆 | B6: 155
A7: 总计 | B7: 600

Sheet 工单明细
A1: order_id | B1: city | C1: service_type | D1: site_id | E1: created_at | F1: dispatched_at | G1: appointment_deadline | H1: arrived_at | I1: completion_deadline | J1: completed_at | K1: order_status | L1: primary_exception | M1: exception_detected_at | N1: exception_closed_at | O1: complaint_flag | P1: rating | Q1: 准时上门标记 | R1: 按期完工标记 | S1: 异常标记 | T1: 已闭环标记 | U1: 待闭环标记 | V1: 计算异常类型 | W1: 源标签一致 | Y1: 来源：03_模拟工单.csv；600 条合成工单，模拟规则见 03_模拟数据说明与验收.md
A2: HS2026080001 | B2: 北京 | C2: 维修 | D2: BJ02 | E2: 46235.333 | F2: 46235.38 | G2: 46238.625 | H2: 46238.64 | I2: 46238.833 | J2: 46238.692 | K2: 已完工 | L2: 上门超时 | M2: 46238.625 | N2: 46238.934 | O2: 0 | P2: 2 | Q2: =IF(AND(ISNUMBER(H2),H2<=G2),1,0) -> 0 | R2: =IF(AND(ISNUMBER(J2),J2<=I2),1,0) -> 1 | S2: =IF(V2="无",0,1) -> 1 | T2: =IF(AND(S2=1,ISNUMBER(N2)),1,0) -> 1 | U2: =IF(AND(S2=1,T2=0),1,0) -> 0 | V2: =IF(AND(ISNUMBER(F2),F2<=G2),IF(AND(ISNUMBER(H2),H2<=G2),IF(AND(ISNUMBER(J2),J2<=I2),"无","完工超时"),"上门超时"),"派单超时") -> 上门超时 | W2: =IF(L2=V2,1,0) -> 1 | Y2: A:P 为原始字段；Q:W 为公式计算列。时间修改后异常类型会重算，W 列提示源标签是否同步。
A3: HS2026080002 | B3: 北京 | C3: 维修 | D3: BJ02 | E3: 46235.358 | F3: 46235.464 | G3: 46237.708 | H3: 46237.684 | I3: 46237.917 | J3: 46237.731 | K3: 已完工 | L3: 无 | O3: 0 | P3: 5 | Q3: =IF(AND(ISNUMBER(H3),H3<=G3),1,0) -> 1 | R3: =IF(AND(ISNUMBER(J3),J3<=I3),1,0) -> 1 | S3: =IF(V3="无",0,1) -> 0 | T3: =IF(AND(S3=1,ISNUMBER(N3)),1,0) -> 0 | U3: =IF(AND(S3=1,T3=0),1,0) -> 0 | V3: =IF(AND(ISNUMBER(F3),F3<=G3),IF(AND(ISNUMBER(H3),H3<=G3),IF(AND(ISNUMBER(J3),J3<=I3),"无","完工超时"),"上门超时"),"派单超时") -> 无 | W3: =IF(L3=V3,1,0) -> 1
A4: HS2026080003 | B4: 北京 | C4: 安装 | D4: BJ02 | E4: 46235.368 | F4: 46235.501 | G4: 46236.625 | H4: 46236.679 | I4: 46236.792 | J4: 46236.748 | K4: 已完工 | L4: 上门超时 | M4: 46236.625 | O4: 1 | P4: 2 | Q4: =IF(AND(ISNUMBER(H4),H4<=G4),1,0) -> 0 | R4: =IF(AND(ISNUMBER(J4),J4<=I4),1,0) -> 1 | S4: =IF(V4="无",0,1) -> 1 | T4: =IF(AND(S4=1,ISNUMBER(N4)),1,0) -> 0 | U4: =IF(AND(S4=1,T4=0),1,0) -> 1 | V4: =IF(AND(ISNUMBER(F4),F4<=G4),IF(AND(ISNUMBER(H4),H4<=G4),IF(AND(ISNUMBER(J4),J4<=I4),"无","完工超时"),"上门超时"),"派单超时") -> 上门超时 | W4: =IF(L4=V4,1,0) -> 1
A5: HS2026080004 | B5: 武汉 | C5: 维修 | D5: WH01 | E5: 46235.392 | F5: 46235.494 | G5: 46237.417 | H5: 46237.376 | I5: 46237.625 | J5: 46237.447 | K5: 已完工 | L5: 无 | O5: 1 | P5: 1 | Q5: =IF(AND(ISNUMBER(H5),H5<=G5),1,0) -> 1 | R5: =IF(AND(ISNUMBER(J5),J5<=I5),1,0) -> 1 | S5: =IF(V5="无",0,1) -> 0 | T5: =IF(AND(S5=1,ISNUMBER(N5)),1,0) -> 0 | U5: =IF(AND(S5=1,T5=0),1,0) -> 0 | V5: =IF(AND(ISNUMBER(F5),F5<=G5),IF(AND(ISNUMBER(H5),H5<=G5),IF(AND(ISNUMBER(J5),J5<=I5),"无","完工超时"),"上门超时"),"派单超时") -> 无 | W5: =IF(L5=V5,1,0) -> 1
A6: HS2026080005 | B6: 北京 | C6: 安装 | D6: BJ01 | E6: 46235.396 | F6: 46235.52 | G6: 46236.625 | H6: 46236.589 | I6: 46236.792 | J6: 46236.645 | K6: 已完工 | L6: 无 | O6: 0 | P6: 5 | Q6: =IF(AND(ISNUMBER(H6),H6<=G6),1,0) -> 1 | R6: =IF(AND(ISNUMBER(J6),J6<=I6),1,0) -> 1 | S6: =IF(V6="无",0,1) -> 0 | T6: =IF(AND(S6=1,ISNUMBER(N6)),1,0) -> 0 | U6: =IF(AND(S6=1,T6=0),1,0) -> 0 | V6: =IF(AND(ISNUMBER(F6),F6<=G6),IF(AND(ISNUMBER(H6),H6<=G6),IF(AND(ISNUMBER(J6),J6<=I6),"无","完工超时"),"上门超时"),"派单超时") -> 无 | W6: =IF(L6=V6,1,0) -> 1
A7: HS2026080006 | B7: 重庆 | C7: 安装 | D7: CQ01 | E7: 46235.427 | F7: 46235.506 | G7: 46236.708 | H7: 46236.681 | I7: 46236.875 | K7: 未完工 | L7: 完工超时 | M7: 46236.875 | O7: 0 | Q7: =IF(AND(ISNUMBER(H7),H7<=G7),1,0) -> 1 | R7: =IF(AND(ISNUMBER(J7),J7<=I7),1,0) -> 0 | S7: =IF(V7="无",0,1) -> 1 | T7: =IF(AND(S7=1,ISNUMBER(N7)),1,0) -> 0 | U7: =IF(AND(S7=1,T7=0),1,0) -> 1 | V7: =IF(AND(ISNUMBER(F7),F7<=G7),IF(AND(ISNUMBER(H7),H7<=G7),IF(AND(ISNUMBER(J7),J7<=I7),"无","完工超时"),"上门超时"),"派单超时") -> 完工超时 | W7: =IF(L7=V7,1,0) -> 1
A8: HS2026080007 | B8: 北京 | C8: 安装 | D8: BJ01 | E8: 46235.469 | F8: 46235.517 | G8: 46236.708 | H8: 46236.7 | I8: 46236.875 | J8: 46236.786 | K8: 已完工 | L8: 无 | O8: 0 | P8: 5 | Q8: =IF(AND(ISNUMBER(H8),H8<=G8),1,0) -> 1 | R8: =IF(AND(ISNUMBER(J8),J8<=I8),1,0) -> 1 | S8: =IF(V8="无",0,1) -> 0 | T8: =IF(AND(S8=1,ISNUMBER(N8)),1,0) -> 0 | U8: =IF(AND(S8=1,T8=0),1,0) -> 0 | V8: =IF(AND(ISNUMBER(F8),F8<=G8),IF(AND(ISNUMBER(H8),H8<=G8),IF(AND(ISNUMBER(J8),J8<=I8),"无","完工超时"),"上门超时"),"派单超时") -> 无 | W8: =IF(L8=V8,1,0) -> 1
A9: HS2026080008 | B9: 重庆 | C9: 安装 | D9: CQ02 | E9: 46235.472 | F9: 46235.544 | G9: 46236.708 | H9: 46236.726 | I9: 46236.875 | J9: 46236.775 | K9: 已完工 | L9: 上门超时 | M9: 46236.708 | N9: 46236.853 | O9: 0 | P9: 4 | Q9: =IF(AND(ISNUMBER(H9),H9<=G9),1,0) -> 0 | R9: =IF(AND(ISNUMBER(J9),J9<=I9),1,0) -> 1 | S9: =IF(V9="无",0,1) -> 1 | T9: =IF(AND(S9=1,ISNUMBER(N9)),1,0) -> 1 | U9: =IF(AND(S9=1,T9=0),1,0) -> 0 | V9: =IF(AND(ISNUMBER(F9),F9<=G9),IF(AND(ISNUMBER(H9),H9<=G9),IF(AND(ISNUMBER(J9),J9<=I9),"无","完工超时"),"上门超时"),"派单超时") -> 上门超时 | W9: =IF(L9=V9,1,0) -> 1
A10: HS2026080009 | B10: 武汉 | C10: 维修 | D10: WH01 | E10: 46235.479 | F10: 46235.591 | G10: 46236.625 | H10: 46236.594 | I10: 46236.833 | J10: 46236.656 | K10: 已完工 | L10: 无 | O10: 0 | P10: 5 | Q10: =IF(AND(ISNUMBER(H10),H10<=G10),1,0) -> 1 | R10: =IF(AND(ISNUMBER(J10),J10<=I10),1,0) -> 1 | S10: =IF(V10="无",0,1) -> 0 | T10: =IF(AND(S10=1,ISNUMBER(N10)),1,0) -> 0 | U10: =IF(AND(S10=1,T10=0),1,0) -> 0 | V10: =IF(AND(ISNUMBER(F10),F10<=G10),IF(AND(ISNUMBER(H10),H10<=G10),IF(AND(ISNUMBER(J10),J10<=I10),"无","完工超时"),"上门超时"),"派单超时") -> 无 | W10: =IF(L10=V10,1,0) -> 1
A11: HS2026080010 | B11: 重庆 | C11: 安装 | D11: CQ02 | E11: 46235.493 | F11: 46235.567 | G11: 46236.417 | H11: 46236.435 | I11: 46236.583 | J11: 46236.485 | K11: 已完工 | L11: 上门超时 | M11: 46236.417 | N11: 46236.595 | O11: 0 | P11: 2 | Q11: =IF(AND(ISNUMBER(H11),H11<=G11),1,0) -> 0 | R11: =IF(AND(ISNUMBER(J11),J11<=I11),1,0) -> 1 | S11: =IF(V11="无",0,1) -> 1 | T11: =IF(AND(S11=1,ISNUMBER(N11)),1,0) -> 1 | U11: =IF(AND(S11=1,T11=0),1,0) -> 0 | V11: =IF(AND(ISNUMBER(F11),F11<=G11),IF(AND(ISNUMBER(H11),H11<=G11),IF(AND(ISNUMBER(J11),J11<=I11),"无","完工超时"),"上门超时"),"派单超时") -> 上门超时 | W11: =IF(L11=V11,1,0) -> 1
A12: HS2026080011 | B12: 武汉 | C12: 维修 | D12: WH01 | E12: 46235.5 | F12: 46235.567 | G12: 46236.5 | H12: 46236.463 | I12: 46236.708 | J12: 46236.541 | K12: 已完工 | L12: 无 | O12: 0 | P12: 5 | Q12: =IF(AND(ISNUMBER(H12),H12<=G12),1,0) -> 1 | R12: =IF(AND(ISNUMBER(J12),J12<=I12),1,0) -> 1 | S12: =IF(V12="无",0,1) -> 0 | T12: =IF(AND(S12=1,ISNUMBER(N12)),1,0) -> 0 | U12: =IF(AND(S12=1,T12=0),1,0) -> 0 | V12: =IF(AND(ISNUMBER(F12),F12<=G12),IF(AND(ISNUMBER(H12),H12<=G12),IF(AND(ISNUMBER(J12),J12<=I12),"无","完工超时"),"上门超时"),"派单超时") -> 无 | W12: =IF(L12=V12,1,0) -> 1
A13: HS2026080012 | B13: 武汉 | C13: 安装 | D13: WH01 | E13: 46235.517 | F13: 46235.61 | G13: 46236.625 | H13: 46236.574 | I13: 46236.792 | J13: 46236.612 | K13: 已完工 | L13: 无 | O13: 0 | P13: 5 | Q13: =IF(AND(ISNUMBER(H13),H13<=G13),1,0) -> 1 | R13: =IF(AND(ISNUMBER(J13),J13<=I13),1,0) -> 1 | S13: =IF(V13="无",0,1) -> 0 | T13: =IF(AND(S13=1,ISNUMBER(N13)),1,0) -> 0 | U13: =IF(AND(S13=1,T13=0),1,0) -> 0 | V13: =IF(AND(ISNUMBER(F13),F13<=G13),IF(AND(ISNUMBER(H13),H13<=G13),IF(AND(ISNUMBER(J13),J13<=I13),"无","完工超时"),"上门超时"),"派单超时") -> 无 | W13: =IF(L13=V13,1,0) -> 1
A14: HS2026080013 | B14: 武汉 | C14: 维修 | D14: WH02 | E14: 46235.535 | G14: 46237.5 | I14: 46237.708 | K14: 未完工 | L14: 派单超时 | M14: 46237.5 | O14: 1 | Q14: =IF(AND(ISNUMBER(H14),H14<=G14),1,0) -> 0 | R14: =IF(AND(ISNUMBER(J14),J14<=I14),1,0) -> 0 | S14: =IF(V14="无",0,1) -> 1 | T14: =IF(AND(S14=1,ISNUMBER(N14)),1,0) -> 0 | U14: =IF(AND(S14=1,T14=0),1,0) -> 1 | V14: =IF(AND(ISNUMBER(F14),F14<=G14),IF(AND(ISNUMBER(H14),H14<=G14),IF(AND(ISNUMBER(J14),J14<=I14),"无","完工超时"),"上门超时"),"派单超时") -> 派单超时 | W14: =IF(L14=V14,1,0) -> 1
A15: HS2026080014 | B15: 重庆 | C15: 维修 | D15: CQ02 | E15: 46235.542 | F15: 46235.69 | G15: 46238.417 | H15: 46238.406 | I15: 46238.625 | J15: 46238.5 | K15: 已完工 | L15: 无 | O15: 0 | P15: 5 | Q15: =IF(AND(ISNUMBER(H15),H15<=G15),1,0) -> 1 | R15: =IF(AND(ISNUMBER(J15),J15<=I15),1,0) -> 1 | S15: =IF(V15="无",0,1) -> 0 | T15: =IF(AND(S15=1,ISNUMBER(N15)),1,0) -> 0 | U15: =IF(AND(S15=1,T15=0),1,0) -> 0 | V15: =IF(AND(ISNUMBER(F15),F15<=G15),IF(AND(ISNUMBER(H15),H15<=G15),IF(AND(ISNUMBER(J15),J15<=I15),"无","完工超时"),"上门超时"),"派单超时") -> 无 | W15: =IF(L15=V15,1,0) -> 1
A16: HS2026080015 | B16: 武汉 | C16: 安装 | D16: WH01 | E16: 46235.556 | F16: 46235.58 | G16: 46236.625 | H16: 46236.674 | I16: 46236.792 | J16: 46236.776 | K16: 已完工 | L16: 上门超时 | M16: 46236.625 | O16: 0 | P16: 3 | Q16: =IF(AND(ISNUMBER(H16),H16<=G16),1,0) -> 0 | R16: =IF(AND(ISNUMBER(J16),J16<=I16),1,0) -> 1 | S16: =IF(V16="无",0,1) -> 1 | T16: =IF(AND(S16=1,ISNUMBER(N16)),1,0) -> 0 | U16: =IF(AND(S16=1,T16=0),1,0) -> 1 | V16: =IF(AND(ISNUMBER(F16),F16<=G16),IF(AND(ISNUMBER(H16),H16<=G16),IF(AND(ISNUMBER(J16),J16<=I16),"无","完工超时"),"上门超时"),"派单超时") -> 上门超时 | W16: =IF(L16=V16,1,0) -> 1
A17: HS2026080016 | B17: 武汉 | C17: 安装 | D17: WH01 | E17: 46235.559 | F17: 46235.647 | G17: 46237.625 | H17: 46237.592 | I17: 46237.792 | J17: 46237.662 | K17: 已完工 | L17: 无 | O17: 0 | P17: 4 | Q17: =IF(AND(ISNUMBER(H17),H17<=G17),1,0) -> 1 | R17: =IF(AND(ISNUMBER(J17),J17<=I17),1,0) -> 1 | S17: =IF(V17="无",0,1) -> 0 | T17: =IF(AND(S17=1,ISNUMBER(N17)),1,0) -> 0 | U17: =IF(AND(S17=1,T17=0),1,0) -> 0 | V17: =IF(AND(ISNUMBER(F17),F17<=G17),IF(AND(ISNUMBER(H17),H17<=G17),IF(AND(ISNUMBER(J17),J17<=I17),"无","完工超时"),"上门超时"),"派单超时") -> 无 | W17: =IF(L17=V17,1,0) -> 1
A18: HS2026080017 | B18: 武汉 | C18: 维修 | D18: WH02 | E18: 46235.562 | G18: 46236.708 | I18: 46236.917 | K18: 未完工 | L18: 派单超时 | M18: 46236.708 | O18: 0 | Q18: =IF(AND(ISNUMBER(H18),H18<=G18),1,0) -> 0 | R18: =IF(AND(ISNUMBER(J18),J18<=I18),1,0) -> 0 | S18: =IF(V18="无",0,1) -> 1 | T18: =IF(AND(S18=1,ISNUMBER(N18)),1,0) -> 0 | U18: =IF(AND(S18=1,T18=0),1,0) -> 1 | V18: =IF(AND(ISNUMBER(F18),F18<=G18),IF(AND(ISNUMBER(H18),H18<=G18),IF(AND(ISNUMBER(J18),J18<=I18),"无","完工超时"),"上门超时"),"派单超时") -> 派单超时 | W18: =IF(L18=V18,1,0) -> 1
A19: HS2026080018 | B19: 重庆 | C19: 安装 | D19: CQ02 | E19: 46235.594 | F19: 46235.733 | G19: 46236.417 | H19: 46236.482 | I19: 46236.583 | J19: 46236.574 | K19: 已完工 | L19: 上门超时 | M19: 46236.417 | N19: 46236.789 | O19: 0 | P19: 2 | Q19: =IF(AND(ISNUMBER(H19),H19<=G19),1,0) -> 0 | R19: =IF(AND(ISNUMBER(J19),J19<=I19),1,0) -> 1 | S19: =IF(V19="无",0,1) -> 1 | T19: =IF(AND(S19=1,ISNUMBER(N19)),1,0) -> 1 | U19: =IF(AND(S19=1,T19=0),1,0) -> 0 | V19: =IF(AND(ISNUMBER(F19),F19<=G19),IF(AND(ISNUMBER(H19),H19<=G19),IF(AND(ISNUMBER(J19),J19<=I19),"无","完工超时"),"上门超时"),"派单超时") -> 上门超时 | W19: =IF(L19=V19,1,0) -> 1
A20: HS2026080019 | B20: 北京 | C20: 维修 | D20: BJ02 | E20: 46235.681 | F20: 46235.772 | G20: 46237.417 | H20: 46237.384 | I20: 46237.625 | J20: 46237.486 | K20: 已完工 | L20: 无 | O20: 0 | P20: 5 | Q20: =IF(AND(ISNUMBER(H20),H20<=G20),1,0) -> 1 | R20: =IF(AND(ISNUMBER(J20),J20<=I20),1,0) -> 1 | S20: =IF(V20="无",0,1) -> 0 | T20: =IF(AND(S20=1,ISNUMBER(N20)),1,0) -> 0 | U20: =IF(AND(S20=1,T20=0),1,0) -> 0 | V20: =IF(AND(ISNUMBER(F20),F20<=G20),IF(AND(ISNUMBER(H20),H20<=G20),IF(AND(ISNUMBER(J20),J20<=I20),"无","完工超时"),"上门超时"),"派单超时") -> 无 | W20: =IF(L20=V20,1,0) -> 1
A21: HS2026080020 | B21: 重庆 | C21: 安装 | D21: CQ02 | E21: 46235.681 | F21: 46235.739 | G21: 46237.417 | H21: 46237.383 | I21: 46237.583 | J21: 46237.483 | K21: 已完工 | L21: 无 | O21: 1 | P21: 2 | Q21: =IF(AND(ISNUMBER(H21),H21<=G21),1,0) -> 1 | R21: =IF(AND(ISNUMBER(J21),J21<=I21),1,0) -> 1 | S21: =IF(V21="无",0,1) -> 0 | T21: =IF(AND(S21=1,ISNUMBER(N21)),1,0) -> 0 | U21: =IF(AND(S21=1,T21=0),1,0) -> 0 | V21: =IF(AND(ISNUMBER(F21),F21<=G21),IF(AND(ISNUMBER(H21),H21<=G21),IF(AND(ISNUMBER(J21),J21<=I21),"无","完工超时"),"上门超时"),"派单超时") -> 无 | W21: =IF(L21=V21,1,0) -> 1
A22: HS2026080021 | B22: 重庆 | C22: 拆旧 | D22: CQ01 | E22: 46235.688 | F22: 46235.771 | G22: 46236.708 | H22: 46236.667 | I22: 46236.833 | J22: 46236.731 | K22: 已完工 | L22: 无 | O22: 0 | P22: 5 | Q22: =IF(AND(ISNUMBER(H22),H22<=G22),1,0) -> 1 | R22: =IF(AND(ISNUMBER(J22),J22<=I22),1,0) -> 1 | S22: =IF(V22="无",0,1) -> 0 | T22: =IF(AND(S22=1,ISNUMBER(N22)),1,0) -> 0 | U22: =IF(AND(S22=1,T22=0),1,0) -> 0 | V22: =IF(AND(ISNUMBER(F22),F22<=G22),IF(AND(ISNUMBER(H22),H22<=G22),IF(AND(ISNUMBER(J22),J22<=I22),"无","完工超时"),"上门超时"),"派单超时") -> 无 | W22: =IF(L22=V22,1,0) -> 1
A23: HS2026080022 | B23: 重庆 | C23: 维修 | D23: CQ02 | E23: 46235.708 | F23: 46235.82 | G23: 46238.417 | H23: 46238.407 | I23: 46238.625 | J23: 46238.707 | K23: 已完工 | L23: 完工超时 | M23: 46238.625 | O23: 0 | P23: 4 | Q23: =IF(AND(ISNUMBER(H23),H23<=G23),1,0) -> 1 | R23: =IF(AND(ISNUMBER(J23),J23<=I23),1,0) -> 0 | S23: =IF(V23="无",0,1) -> 1 | T23: =IF(AND(S23=1,ISNUMBER(N23)),1,0) -> 0 | U23: =IF(AND(S23=1,T23=0),1,0) -> 1 | V23: =IF(AND(ISNUMBER(F23),F23<=G23),IF(AND(ISNUMBER(H23),H23<=G23),IF(AND(ISNUMBER(J23),J23<=I23),"无","完工超时"),"上门超时"),"派单超时") -> 完工超时 | W23: =IF(L23=V23,1,0) -> 1
A24: HS2026080023 | B24: 北京 | C24: 安装 | D24: BJ01 | E24: 46235.774 | F24: 46235.811 | G24: 46236.5 | H24: 46236.487 | I24: 46236.667 | J24: 46236.562 | K24: 已完工 | L24: 无 | O24: 0 | P24: 5 | Q24: =IF(AND(ISNUMBER(H24),H24<=G24),1,0) -> 1 | R24: =IF(AND(ISNUMBER(J24),J24<=I24),1,0) -> 1 | S24: =IF(V24="无",0,1) -> 0 | T24: =IF(AND(S24=1,ISNUMBER(N24)),1,0) -> 0 | U24: =IF(AND(S24=1,T24=0),1,0) -> 0 | V24: =IF(AND(ISNUMBER(F24),F24<=G24),IF(AND(ISNUMBER(H24),H24<=G24),IF(AND(ISNUMBER(J24),J24<=I24),"无","完工超时"),"上门超时"),"派单超时") -> 无 | W24: =IF(L24=V24,1,0) -> 1
A25: HS2026080024 | B25: 重庆 | C25: 安装 | D25: CQ02 | E25: 46235.785 | F25: 46235.882 | G25: 46236.417 | H25: 46236.391 | I25: 46236.583 | J25: 46236.428 | K25: 已完工 | L25: 无 | O25: 0 | P25: 4 | Q25: =IF(AND(ISNUMBER(H25),H25<=G25),1,0) -> 1 | R25: =IF(AND(ISNUMBER(J25),J25<=I25),1,0) -> 1 | S25: =IF(V25="无",0,1) -> 0 | T25: =IF(AND(S25=1,ISNUMBER(N25)),1,0) -> 0 | U25: =IF(AND(S25=1,T25=0),1,0) -> 0 | V25: =IF(AND(ISNUMBER(F25),F25<=G25),IF(AND(ISNUMBER(H25),H25<=G25),IF(AND(ISNUMBER(J25),J25<=I25),"无","完工超时"),"上门超时"),"派单超时") -> 无 | W25: =IF(L25=V25,1,0) -> 1
A26: HS2026080025 | B26: 武汉 | C26: 维修 | D26: WH02 | E26: 46236.354 | F26: 46236.426 | G26: 46238.5 | H26: 46238.479 | I26: 46238.708 | K26: 未完工 | L26: 完工超时 | M26: 46238.708 | O26: 0 | Q26: =IF(AND(ISNUMBER(H26),H26<=G26),1,0) -> 1 | R26: =IF(AND(ISNUMBER(J26),J26<=I26),1,0) -> 0 | S26: =IF(V26="无",0,1) -> 1 | T26: =IF(AND(S26=1,ISNUMBER(N26)),1,0) -> 0 | U26: =IF(AND(S26=1,T26=0),1,0) -> 1 | V26: =IF(AND(ISNUMBER(F26),F26<=G26),IF(AND(ISNUMBER(H26),H26<=G26),IF(AND(ISNUMBER(J26),J26<=I26),"无","完工超时"),"上门超时"),"派单超时") -> 完工超时 | W26: =IF(L26=V26,1,0) -> 1
A27: HS2026080026 | B27: 武汉 | C27: 安装 | D27: WH02 | E27: 46236.372 | F27: 46236.451 | G27: 46237.625 | H27: 46237.599 | I27: 46237.792 | J27: 46237.674 | K27: 已完工 | L27: 无 | O27: 0 | P27: 5 | Q27: =IF(AND(ISNUMBER(H27),H27<=G27),1,0) -> 1 | R27: =IF(AND(ISNUMBER(J27),J27<=I27),1,0) -> 1 | S27: =IF(V27="无",0,1) -> 0 | T27: =IF(AND(S27=1,ISNUMBER(N27)),1,0) -> 0 | U27: =IF(AND(S27=1,T27=0),1,0) -> 0 | V27: =IF(AND(ISNUMBER(F27),F27<=G27),IF(AND(ISNUMBER(H27),H27<=G27),IF(AND(ISNUMBER(J27),J27<=I27),"无","完工超时"),"上门超时"),"派单超时") -> 无 | W27: =IF(L27=V27,1,0) -> 1
A28: HS2026080027 | B28: 武汉 | C28: 维修 | D28: WH01 | E28: 46236.378 | F28: 46236.522 | G28: 46237.417 | H28: 46237.381 | I28: 46237.625 | J28: 46237.44 | K28: 已完工 | L28: 无 | O28: 0 | P28: 5 | Q28: =IF(AND(ISNUMBER(H28),H28<=G28),1,0) -> 1 | R28: =IF(AND(ISNUMBER(J28),J28<=I28),1,0) -> 1 | S28: =IF(V28="无",0,1) -> 0 | T28: =IF(AND(S28=1,ISNUMBER(N28)),1,0) -> 0 | U28: =IF(AND(S28=1,T28=0),1,0) -> 0 | V28: =IF(AND(ISNUMBER(F28),F28<=G28),IF(AND(ISNUMBER(H28),H28<=G28),IF(AND(ISNUMBER(J28),J28<=I28),"无","完工超时"),"上门超时"),"派单超时") -> 无 | W28: =IF(L28=V28,1,0) -> 1
A29: HS2026080028 | B29: 重庆 | C29: 安装 | D29: CQ02 | E29: 46236.382 | F29: 46236.537 | G29: 46237.625 | H29: 46237.594 | I29: 46237.792 | J29: 46237.829 | K29: 已完工 | L29: 完工超时 | M29: 46237.792 | N29: 46237.877 | O29: 1 | Q29: =IF(AND(ISNUMBER(H29),H29<=G29),1,0) -> 1 | R29: =IF(AND(ISNUMBER(J29),J29<=I29),1,0) -> 0 | S29: =IF(V29="无",0,1) -> 1 | T29: =IF(AND(S29=1,ISNUMBER(N29)),1,0) -> 1 | U29: =IF(AND(S29=1,T29=0),1,0) -> 0 | V29: =IF(AND(ISNUMBER(F29),F29<=G29),IF(AND(ISNUMBER(H29),H29<=G29),IF(AND(ISNUMBER(J29),J29<=I29),"无","完工超时"),"上门超时"),"派单超时") -> 完工超时 | W29: =IF(L29=V29,1,0) -> 1
A30: HS2026080029 | B30: 北京 | C30: 维修 | D30: BJ02 | E30: 46236.427 | F30: 46236.587 | G30: 46239.625 | H30: 46239.579 | I30: 46239.833 | J30: 46239.639 | K30: 已完工 | L30: 无 | O30: 0 | Q30: =IF(AND(ISNUMBER(H30),H30<=G30),1,0) -> 1 | R30: =IF(AND(ISNUMBER(J30),J30<=I30),1,0) -> 1 | S30: =IF(V30="无",0,1) -> 0 | T30: =IF(AND(S30=1,ISNUMBER(N30)),1,0) -> 0 | U30: =IF(AND(S30=1,T30=0),1,0) -> 0 | V30: =IF(AND(ISNUMBER(F30),F30<=G30),IF(AND(ISNUMBER(H30),H30<=G30),IF(AND(ISNUMBER(J30),J30<=I30),"无","完工超时"),"上门超时"),"派单超时") -> 无 | W30: =IF(L30=V30,1,0) -> 1
A31: HS2026080030 | B31: 武汉 | C31: 维修 | D31: WH02 | E31: 46236.431 | F31: 46236.576 | G31: 46238.625 | H31: 46238.617 | I31: 46238.833 | J31: 46238.713 | K31: 已完工 | L31: 无 | O31: 0 | P31: 5 | Q31: =IF(AND(ISNUMBER(H31),H31<=G31),1,0) -> 1 | R31: =IF(AND(ISNUMBER(J31),J31<=I31),1,0) -> 1 | S31: =IF(V31="无",0,1) -> 0 | T31: =IF(AND(S31=1,ISNUMBER(N31)),1,0) -> 0 | U31: =IF(AND(S31=1,T31=0),1,0) -> 0 | V31: =IF(AND(ISNUMBER(F31),F31<=G31),IF(AND(ISNUMBER(H31),H31<=G31),IF(AND(ISNUMBER(J31),J31<=I31),"无","完工超时"),"上门超时"),"派单超时") -> 无 | W31: =IF(L31=V31,1,0) -> 1
A32: HS2026080031 | B32: 武汉 | C32: 安装 | D32: WH02 | E32: 46236.434 | F32: 46236.569 | G32: 46239.625 | H32: 46239.576 | I32: 46239.792 | J32: 46239.644 | K32: 已完工 | L32: 无 | O32: 0 | P32: 3 | Q32: =IF(AND(ISNUMBER(H32),H32<=G32),1,0) -> 1 | R32: =IF(AND(ISNUMBER(J32),J32<=I32),1,0) -> 1 | S32: =IF(V32="无",0,1) -> 0 | T32: =IF(AND(S32=1,ISNUMBER(N32)),1,0) -> 0 | U32: =IF(AND(S32=1,T32=0),1,0) -> 0 | V32: =IF(AND(ISNUMBER(F32),F32<=G32),IF(AND(ISNUMBER(H32),H32<=G32),IF(AND(ISNUMBER(J32),J32<=I32),"无","完工超时"),"上门超时"),"派单超时") -> 无 | W32: =IF(L32=V32,1,0) -> 1
A33: HS2026080032 | B33: 北京 | C33: 维修 | D33: BJ02 | E33: 46236.458 | F33: 46236.557 | G33: 46237.708 | H33: 46237.674 | I33: 46237.917 | J33: 46237.99 | K33: 已完工 | L33: 完工超时 | M33: 46237.917 | N33: 46238.024 | O33: 0 | P33: 4 | Q33: =IF(AND(ISNUMBER(H33),H33<=G33),1,0) -> 1 | R33: =IF(AND(ISNUMBER(J33),J33<=I33),1,0) -> 0 | S33: =IF(V33="无",0,1) -> 1 | T33: =IF(AND(S33=1,ISNUMBER(N33)),1,0) -> 1 | U33: =IF(AND(S33=1,T33=0),1,0) -> 0 | V33: =IF(AND(ISNUMBER(F33),F33<=G33),IF(AND(ISNUMBER(H33),H33<=G33),IF(AND(ISNUMBER(J33),J33<=I33),"无","完工超时"),"上门超时"),"派单超时") -> 完工超时 | W33: =IF(L33=V33,1,0) -> 1
A34: HS2026080033 | B34: 重庆 | C34: 安装 | D34: CQ02 | E34: 46236.465 | F34: 46236.505 | G34: 46237.625 | H34: 46237.606 | I34: 46237.792 | J34: 46237.708 | K34: 已完工 | L34: 无 | O34: 0 | P34: 4 | Q34: =IF(AND(ISNUMBER(H34),H34<=G34),1,0) -> 1 | R34: =IF(AND(ISNUMBER(J34),J34<=I34),1,0) -> 1 | S34: =IF(V34="无",0,1) -> 0 | T34: =IF(AND(S34=1,ISNUMBER(N34)),1,0) -> 0 | U34: =IF(AND(S34=1,T34=0),1,0) -> 0 | V34: =IF(AND(ISNUMBER(F34),F34<=G34),IF(AND(ISNUMBER(H34),H34<=G34),IF(AND(ISNUMBER(J34),J34<=I34),"无","完工超时"),"上门超时"),"派单超时") -> 无 | W34: =IF(L34=V34,1,0) -> 1
A35: HS2026080034 | B35: 武汉 | C35: 安装 | D35: WH01 | E35: 46236.483 | F35: 46236.611 | G35: 46238.625 | H35: 46238.606 | I35: 46238.792 | J35: 46238.69 | K35: 已完工 | L35: 无 | O35: 0 | P35: 4 | Q35: =IF(AND(ISNUMBER(H35),H35<=G35),1,0) -> 1 | R35: =IF(AND(ISNUMBER(J35),J35<=I35),1,0) -> 1 | S35: =IF(V35="无",0,1) -> 0 | T35: =IF(AND(S35=1,ISNUMBER(N35)),1,0) -> 0 | U35: =IF(AND(S35=1,T35=0),1,0) -> 0 | V35: =IF(AND(ISNUMBER(F35),F35<=G35),IF(AND(ISNUMBER(H35),H35<=G35),IF(AND(ISNUMBER(J35),J35<=I35),"无","完工超时"),"上门超时"),"派单超时") -> 无 | W35: =IF(L35=V35,1,0) -> 1
A36: HS2026080035 | B36: 北京 | C36: 拆旧 | D36: BJ02 | E36: 46236.493 | F36: 46236.611 | G36: 46238.625 | H36: 46238.6 | I36: 46238.75 | J36: 46238.692 | K36: 已完工 | L36: 无 | O36: 0 | P36: 4 | Q36: =IF(AND(ISNUMBER(H36),H36<=G36),1,0) -> 1 | R36: =IF(AND(ISNUMBER(J36),J36<=I36),1,0) -> 1 | S36: =IF(V36="无",0,1) -> 0 | T36: =IF(AND(S36=1,ISNUMBER(N36)),1,0) -> 0 | U36: =IF(AND(S36=1,T36=0),1,0) -> 0 | V36: =IF(AND(ISNUMBER(F36),F36<=G36),IF(AND(ISNUMBER(H36),H36<=G36),IF(AND(ISNUMBER(J36),J36<=I36),"无","完工超时"),"上门超时"),"派单超时") -> 无 | W36: =IF(L36=V36,1,0) -> 1
A37: HS2026080036 | B37: 重庆 | C37: 维修 | D37: CQ02 | E37: 46236.503 | F37: 46236.59 | G37: 46237.5 | H37: 46237.526 | I37: 46237.708 | J37: 46237.617 | K37: 已完工 | L37: 上门超时 | M37: 46237.5 | N37: 46237.648 | O37: 0 | P37: 2 | Q37: =IF(AND(ISNUMBER(H37),H37<=G37),1,0) -> 0 | R37: =IF(AND(ISNUMBER(J37),J37<=I37),1,0) -> 1 | S37: =IF(V37="无",0,1) -> 1 | T37: =IF(AND(S37=1,ISNUMBER(N37)),1,0) -> 1 | U37: =IF(AND(S37=1,T37=0),1,0) -> 0 | V37: =IF(AND(ISNUMBER(F37),F37<=G37),IF(AND(ISNUMBER(H37),H37<=G37),IF(AND(ISNUMBER(J37),J37<=I37),"无","完工超时"),"上门超时"),"派单超时") -> 上门超时 | W37: =IF(L37=V37,1,0) -> 1
A38: HS2026080037 | B38: 重庆 | C38: 安装 | D38: CQ02 | E38: 46236.514 | F38: 46236.669 | G38: 46238.708 | H38: 46238.697 | I38: 46238.875 | J38: 46238.791 | K38: 已完工 | L38: 无 | O38: 0 | P38: 5 | Q38: =IF(AND(ISNUMBER(H38),H38<=G38),1,0) -> 1 | R38: =IF(AND(ISNUMBER(J38),J38<=I38),1,0) -> 1 | S38: =IF(V38="无",0,1) -> 0 | T38: =IF(AND(S38=1,ISNUMBER(N38)),1,0) -> 0 | U38: =IF(AND(S38=1,T38=0),1,0) -> 0 | V38: =IF(AND(ISNUMBER(F38),F38<=G38),IF(AND(ISNUMBER(H38),H38<=G38),IF(AND(ISNUMBER(J38),J38<=I38),"无","完工超时"),"上门超时"),"派单超时") -> 无 | W38: =IF(L38=V38,1,0) -> 1
A39: HS2026080038 | B39: 武汉 | C39: 安装 | D39: WH01 | E39: 46236.524 | F39: 46236.685 | G39: 46238.625 | I39: 46238.792 | K39: 未完工 | L39: 上门超时 | M39: 46238.625 | O39: 0 | Q39: =IF(AND(ISNUMBER(H39),H39<=G39),1,0) -> 0 | R39: =IF(AND(ISNUMBER(J39),J39<=I39),1,0) -> 0 | S39: =IF(V39="无",0,1) -> 1 | T39: =IF(AND(S39=1,ISNUMBER(N39)),1,0) -> 0 | U39: =IF(AND(S39=1,T39=0),1,0) -> 1 | V39: =IF(AND(ISNUMBER(F39),F39<=G39),IF(AND(ISNUMBER(H39),H39<=G39),IF(AND(ISNUMBER(J39),J39<=I39),"无","完工超时"),"上门超时"),"派单超时") -> 上门超时 | W39: =IF(L39=V39,1,0) -> 1
A40: HS2026080039 | B40: 北京 | C40: 安装 | D40: BJ01 | E40: 46236.528 | F40: 46236.561 | G40: 46239.625 | H40: 46239.616 | I40: 46239.792 | J40: 46239.713 | K40: 已完工 | L40: 无 | O40: 0 | P40: 5 | Q40: =IF(AND(ISNUMBER(H40),H40<=G40),1,0) -> 1 | R40: =IF(AND(ISNUMBER(J40),J40<=I40),1,0) -> 1 | S40: =IF(V40="无",0,1) -> 0 | T40: =IF(AND(S40=1,ISNUMBER(N40)),1,0) -> 0 | U40: =IF(AND(S40=1,T40=0),1,0) -> 0 | V40: =IF(AND(ISNUMBER(F40),F40<=G40),IF(AND(ISNUMBER(H40),H40<=G40),IF(AND(ISNUMBER(J40),J40<=I40),"无","完工超时"),"上门超时"),"派单超时") -> 无 | W40: =IF(L40=V40,1,0) -> 1
...
